<?xml version="1.0"?>
<robot name="C:/Users/lenih/1_RWTH/0_Projects/Pfadplanung/Spatiotemporal-Pfadplanung/Pfadplanung_Program/Simulation/protos/Moose.urdf" xmlns:xacro="http://ros.org/wiki/xacro">
  <link name="base_link">
    <visual>
      <origin xyz="0 0 0.15" rpy="1.570796 0 0"/>
      <geometry>
        <box size="2.96 0.5 1.4"/>
      </geometry>
    </visual>
    <collision>
      <origin xyz="0 0 0.15" rpy="1.570796 0 0"/>
      <geometry>
        <box size="2.96 0.5 1.4"/>
      </geometry>
    </collision>
    <visual>
      <origin xyz="-1.31 0 0.56" rpy="1.570796 0 0"/>
      <geometry>
        <box size="0.35 0.32 0.7"/>
      </geometry>
    </visual>
    <collision>
      <origin xyz="-1.31 0 0.56" rpy="1.570796 0 0"/>
      <geometry>
        <box size="0.35 0.32 0.7"/>
      </geometry>
    </collision>
    <visual>
      <origin xyz="-1.29 0.53 0.49" rpy="1.570796 0 0"/>
      <geometry>
        <box size="0.28 0.18 0.33"/>
      </geometry>
    </visual>
    <collision>
      <origin xyz="-1.29 0.53 0.49" rpy="1.570796 0 0"/>
      <geometry>
        <box size="0.28 0.18 0.33"/>
      </geometry>
    </collision>
    <visual>
      <origin xyz="-1.29 -0.53 0.49" rpy="1.570796 0 0"/>
      <geometry>
        <box size="0.28 0.18 0.33"/>
      </geometry>
    </visual>
    <collision>
      <origin xyz="-1.29 -0.53 0.49" rpy="1.570796 0 0"/>
      <geometry>
        <box size="0.28 0.18 0.33"/>
      </geometry>
    </collision>
    <visual>
      <origin xyz="1.25 -0.53 0.49" rpy="1.570796 0 0"/>
      <geometry>
        <box size="0.28 0.18 0.33"/>
      </geometry>
    </visual>
    <collision>
      <origin xyz="1.25 -0.53 0.49" rpy="1.570796 0 0"/>
      <geometry>
        <box size="0.28 0.18 0.33"/>
      </geometry>
    </collision>
    <visual>
      <origin xyz="1.25 0.53 0.49" rpy="1.570796 0 0"/>
      <geometry>
        <box size="0.28 0.18 0.33"/>
      </geometry>
    </visual>
    <collision>
      <origin xyz="1.25 0.53 0.49" rpy="1.570796 0 0"/>
      <geometry>
        <box size="0.28 0.18 0.33"/>
      </geometry>
    </collision>
  </link>
  <joint name="left motor 4" type="continuous">
    <parent link="base_link"/>
    <child link="left wheel 4"/>
    <axis xyz="0 1 0"/>
    <limit effort="1000" velocity="26"/>
    <origin xyz="-1.1 0.6 -0.06" rpy="0 0 0"/>
  </joint>
  <link name="left wheel 4">
    <visual>
      <origin xyz="0 0 0" rpy="1.570796 0 0"/>
      <geometry>
        <cylinder radius="0.32" length="0.35"/>
      </geometry>
    </visual>
    <collision>
      <origin xyz="0 0 0" rpy="1.570796 0 0"/>
      <geometry>
        <cylinder radius="0.32" length="0.35"/>
      </geometry>
    </collision>
  </link>
  <joint name="slot_left wheel 4_joint" type="fixed">
    <parent link="slot"/>
    <child link="left wheel 4"/>
    <origin xyz="0 0 0" rpy="0 0 0"/>
  </joint>
  <joint name="left motor 3" type="continuous">
    <parent link="base_link"/>
    <child link="left wheel 3"/>
    <axis xyz="0 1 0"/>
    <limit effort="1000" velocity="26"/>
    <origin xyz="-0.42 0.6 -0.06" rpy="0 0 0"/>
  </joint>
  <link name="left wheel 3">
    <visual>
      <origin xyz="0 0 0" rpy="1.570796 0 0"/>
      <geometry>
        <cylinder radius="0.32" length="0.35"/>
      </geometry>
    </visual>
    <collision>
      <origin xyz="0 0 0" rpy="1.570796 0 0"/>
      <geometry>
        <cylinder radius="0.32" length="0.35"/>
      </geometry>
    </collision>
  </link>
  <joint name="slot_0_left wheel 3_joint" type="fixed">
    <parent link="slot_0"/>
    <child link="left wheel 3"/>
    <origin xyz="0 0 0" rpy="0 0 0"/>
  </joint>
  <joint name="left motor 2" type="continuous">
    <parent link="base_link"/>
    <child link="left wheel 2"/>
    <axis xyz="0 1 0"/>
    <limit effort="1000" velocity="26"/>
    <origin xyz="0.27 0.6 -0.06" rpy="0 0 0"/>
  </joint>
  <link name="left wheel 2">
    <visual>
      <origin xyz="0 0 0" rpy="1.570796 0 0"/>
      <geometry>
        <cylinder radius="0.32" length="0.35"/>
      </geometry>
    </visual>
    <collision>
      <origin xyz="0 0 0" rpy="1.570796 0 0"/>
      <geometry>
        <cylinder radius="0.32" length="0.35"/>
      </geometry>
    </collision>
  </link>
  <joint name="slot_1_left wheel 2_joint" type="fixed">
    <parent link="slot_1"/>
    <child link="left wheel 2"/>
    <origin xyz="0 0 0" rpy="0 0 0"/>
  </joint>
  <joint name="left motor 1" type="continuous">
    <parent link="base_link"/>
    <child link="left wheel 1"/>
    <axis xyz="0 1 0"/>
    <limit effort="1000" velocity="26"/>
    <origin xyz="0.95 0.6 -0.06" rpy="0 0 0"/>
  </joint>
  <link name="left wheel 1">
    <visual>
      <origin xyz="0 0 0" rpy="1.570796 0 0"/>
      <geometry>
        <cylinder radius="0.32" length="0.35"/>
      </geometry>
    </visual>
    <collision>
      <origin xyz="0 0 0" rpy="1.570796 0 0"/>
      <geometry>
        <cylinder radius="0.32" length="0.35"/>
      </geometry>
    </collision>
  </link>
  <joint name="slot_2_left wheel 1_joint" type="fixed">
    <parent link="slot_2"/>
    <child link="left wheel 1"/>
    <origin xyz="0 0 0" rpy="0 0 0"/>
  </joint>
  <joint name="right motor 4" type="continuous">
    <parent link="base_link"/>
    <child link="right wheel 4"/>
    <axis xyz="0 -1 0"/>
    <limit effort="1000" velocity="26"/>
    <origin xyz="-1.1 -0.6 -0.06" rpy="0 0 3.14159"/>
  </joint>
  <link name="right wheel 4">
    <visual>
      <origin xyz="0 0 0" rpy="1.570796 0 0"/>
      <geometry>
        <cylinder radius="0.32" length="0.35"/>
      </geometry>
    </visual>
    <collision>
      <origin xyz="0 0 0" rpy="1.570796 0 0"/>
      <geometry>
        <cylinder radius="0.32" length="0.35"/>
      </geometry>
    </collision>
  </link>
  <joint name="slot_3_right wheel 4_joint" type="fixed">
    <parent link="slot_3"/>
    <child link="right wheel 4"/>
    <origin xyz="0 0 0" rpy="0 0 0"/>
  </joint>
  <joint name="right motor 3" type="continuous">
    <parent link="base_link"/>
    <child link="right wheel 3"/>
    <axis xyz="0 -1 0"/>
    <limit effort="1000" velocity="26"/>
    <origin xyz="-0.42 -0.6 -0.06" rpy="0 0 3.14159"/>
  </joint>
  <link name="right wheel 3">
    <visual>
      <origin xyz="0 0 0" rpy="1.570796 0 0"/>
      <geometry>
        <cylinder radius="0.32" length="0.35"/>
      </geometry>
    </visual>
    <collision>
      <origin xyz="0 0 0" rpy="1.570796 0 0"/>
      <geometry>
        <cylinder radius="0.32" length="0.35"/>
      </geometry>
    </collision>
  </link>
  <joint name="slot_4_right wheel 3_joint" type="fixed">
    <parent link="slot_4"/>
    <child link="right wheel 3"/>
    <origin xyz="0 0 0" rpy="0 0 0"/>
  </joint>
  <joint name="right motor 2" type="continuous">
    <parent link="base_link"/>
    <child link="right wheel 2"/>
    <axis xyz="0 -1 0"/>
    <limit effort="1000" velocity="26"/>
    <origin xyz="0.27 -0.6 -0.06" rpy="0 0 3.14159"/>
  </joint>
  <link name="right wheel 2">
    <visual>
      <origin xyz="0 0 0" rpy="1.570796 0 0"/>
      <geometry>
        <cylinder radius="0.32" length="0.35"/>
      </geometry>
    </visual>
    <collision>
      <origin xyz="0 0 0" rpy="1.570796 0 0"/>
      <geometry>
        <cylinder radius="0.32" length="0.35"/>
      </geometry>
    </collision>
  </link>
  <joint name="slot_5_right wheel 2_joint" type="fixed">
    <parent link="slot_5"/>
    <child link="right wheel 2"/>
    <origin xyz="0 0 0" rpy="0 0 0"/>
  </joint>
  <joint name="right motor 1" type="continuous">
    <parent link="base_link"/>
    <child link="right wheel 1"/>
    <axis xyz="0 -1 0"/>
    <limit effort="1000" velocity="26"/>
    <origin xyz="0.95 -0.6 -0.06" rpy="0 0 3.14159"/>
  </joint>
  <link name="right wheel 1">
    <visual>
      <origin xyz="0 0 0" rpy="1.570796 0 0"/>
      <geometry>
        <cylinder radius="0.32" length="0.35"/>
      </geometry>
    </visual>
    <collision>
      <origin xyz="0 0 0" rpy="1.570796 0 0"/>
      <geometry>
        <cylinder radius="0.32" length="0.35"/>
      </geometry>
    </collision>
  </link>
  <joint name="slot_6_right wheel 1_joint" type="fixed">
    <parent link="slot_6"/>
    <child link="right wheel 1"/>
    <origin xyz="0 0 0" rpy="0 0 0"/>
  </joint>
  <link name="gps">
  </link>
  <joint name="base_link_gps_joint" type="fixed">
    <parent link="base_link"/>
    <child link="gps"/>
    <origin xyz="0 0 0.4" rpy="0 0 0"/>
  </joint>
  <link name="compass">
  </link>
  <joint name="base_link_compass_joint" type="fixed">
    <parent link="base_link"/>
    <child link="compass"/>
    <origin xyz="0 0 0.4" rpy="0 0 0"/>
  </joint>
</robot>
